<?xml version='1.0' encoding='utf-8'?>
<robot name="robotis_op3">
  <gazebo>
    <plugin filename="libgazebo_ros_control.so" name="gazebo_ros_control">
      <robotNamespace>/robotis_op3</robotNamespace>
      </plugin>
    </gazebo>
  <gazebo reference="body_link">
    <mu1>0.2</mu1>
    <mu2>0.2</mu2>
    <material>Gazebo/White</material>
    <selfCollide>false</selfCollide>
    </gazebo>
  <gazebo reference="l_hip_yaw_link">
    <mu1>0.2</mu1>
    <mu2>0.2</mu2>
    <material>Gazebo/White</material>
    <selfCollide>false</selfCollide>
    </gazebo>
  <gazebo reference="l_hip_roll_link">
    <mu1>0.2</mu1>
    <mu2>0.2</mu2>
    <material>Gazebo/White</material>
    <selfCollide>false</selfCollide>
    </gazebo>
  <gazebo reference="l_hip_pitch_link">
    <mu1>0.2</mu1>
    <mu2>0.2</mu2>
    <material>Gazebo/White</material>
    <selfCollide>false</selfCollide>
    </gazebo>
  <gazebo reference="l_knee_link">
    <mu1>0.2</mu1>
    <mu2>0.2</mu2>
    <material>Gazebo/White</material>
    <selfCollide>false</selfCollide>
    </gazebo>
  <gazebo reference="l_ank_pitch_link">
    <mu1>0.2</mu1>
    <mu2>0.2</mu2>
    <material>Gazebo/White</material>
    <selfCollide>false</selfCollide>
    </gazebo>
  <gazebo reference="l_ank_roll_link">
    <kp>100000.0</kp>
    <kd>100.0</kd>
    <mu1>1.5</mu1>
    <mu2>1.5</mu2>
    <fdir1>1 0 0</fdir1>
    <maxVel>1.0</maxVel>
    <minDepth>0.001</minDepth>
    <material>Gazebo/White</material>
    </gazebo>
  <gazebo reference="r_hip_yaw_link">
    <mu1>0.2</mu1>
    <mu2>0.2</mu2>
    <material>Gazebo/White</material>
    <selfCollide>false</selfCollide>
    </gazebo>
  <gazebo reference="r_hip_roll_link">
    <mu1>0.2</mu1>
    <mu2>0.2</mu2>
    <material>Gazebo/White</material>
    <selfCollide>false</selfCollide>
    </gazebo>
  <gazebo reference="r_hip_pitch_link">
    <mu1>0.2</mu1>
    <mu2>0.2</mu2>
    <material>Gazebo/White</material>
    <selfCollide>false</selfCollide>
    </gazebo>
  <gazebo reference="r_knee_link">
    <mu1>0.2</mu1>
    <mu2>0.2</mu2>
    <material>Gazebo/White</material>
    <selfCollide>false</selfCollide>
    </gazebo>
  <gazebo reference="r_ank_pitch_link">
    <mu1>0.2</mu1>
    <mu2>0.2</mu2>
    <material>Gazebo/White</material>
    <selfCollide>false</selfCollide>
    </gazebo>
  <gazebo reference="r_ank_roll_link">
    <mu1>9000</mu1>
    <kp>100000.0</kp>
    <kd>100.0</kd>
    <mu1>1.5</mu1>
    <mu2>1.5</mu2>
    <fdir1>1 0 0</fdir1>
    <maxVel>1.0</maxVel>
    <minDepth>0.001</minDepth>
    <material>Gazebo/White</material>
    </gazebo>
  <gazebo reference="r_sho_pitch_link">
    <mu1>0.2</mu1>
    <mu2>0.2</mu2>
    <material>Gazebo/White</material>
    <selfCollide>false</selfCollide>
    </gazebo>
  <gazebo reference="r_sho_roll_link">
    <mu1>0.2</mu1>
    <mu2>0.2</mu2>
    <material>Gazebo/White</material>
    <selfCollide>false</selfCollide>
    </gazebo>
  <gazebo reference="r_el_link">
    <mu1>0.2</mu1>
    <mu2>0.2</mu2>
    <material>Gazebo/White</material>
    <selfCollide>false</selfCollide>
    </gazebo>
  <gazebo reference="l_sho_pitch_link">
    <mu1>0.2</mu1>
    <mu2>0.2</mu2>
    <material>Gazebo/White</material>
    <selfCollide>false</selfCollide>
    </gazebo>
  <gazebo reference="l_sho_roll_link">
    <mu1>0.2</mu1>
    <mu2>0.2</mu2>
    <material>Gazebo/White</material>
    <selfCollide>false</selfCollide>
    </gazebo>
  <gazebo reference="l_el_link">
    <mu1>0.2</mu1>
    <mu2>0.2</mu2>
    <material>Gazebo/White</material>
    <selfCollide>false</selfCollide>
    </gazebo>
  <gazebo reference="head_pan_link">
    <mu1>0.2</mu1>
    <mu2>0.2</mu2>
    <material>Gazebo/White</material>
    <selfCollide>false</selfCollide>
    </gazebo>
  <gazebo reference="head_tilt_link">
    <mu1>0.2</mu1>
    <mu2>0.2</mu2>
    <material>Gazebo/White</material>
    <selfCollide>false</selfCollide>
    </gazebo>
  <gazebo reference="cam_gazebo_link">
    <sensor name="camera" type="camera">
      <pose>-0.050000 -0.010000 0.000000 -1.5708 0.000000 -3.141592</pose>
      <camera name="__default__">
        <horizontal_fov>1.012300</horizontal_fov>
        <image>
          <width>320</width>
          <height>200</height>
          </image>
        <clip>
          <near>0.001000</near>
          <far>100.000000</far>
          </clip>
        </camera>
      <always_on>1</always_on>
      <update_rate>30.000000</update_rate>
      <visualize>1</visualize>
      <plugin filename="libgazebo_ros_camera.so" name="camera_controller">
        <alwaysOn>true</alwaysOn>
        <updateRate>30</updateRate>
        <cameraName>robotis_op3/camera</cameraName>
        <imageTopicName>image_raw</imageTopicName>
        <cameraInfoTopicName>camera_info</cameraInfoTopicName>
        <frameName>cam_link</frameName>
        <hackBaseline>0.07</hackBaseline>
        <distortionK1>0.0</distortionK1>
        <distortionK2>0.0</distortionK2>
        <distortionK3>0.0</distortionK3>
        <distortionT1>0.0</distortionT1>
        <distortionT2>0.0</distortionT2>
        </plugin>
      </sensor>
    </gazebo>
  <gazebo reference="body_link">
    <gravity>true</gravity>
    <sensor name="imu_sensor" type="imu">
      <always_on>true</always_on>
      <update_rate>100</update_rate>
      <visualize>true</visualize>
      <topic>__default_topic__</topic>
      <plugin filename="libgazebo_ros_imu_sensor.so" name="imu_plugin">
        <topicName>robotis_op3/imu</topicName>
        <bodyName>body_link</bodyName>
        <updateRateHZ>10.0</updateRateHZ>
        <gaussianNoise>0.0</gaussianNoise>
        <xyzOffset>0 0 0</xyzOffset>
        <rpyOffset>0 0 0</rpyOffset>
        <frameName>body_link</frameName>
        </plugin>
      <pose>0 0 0 0 0 0</pose>
      </sensor>
    </gazebo>
  <link name="body_link">
    <visual>
      <origin rpy="0 0 0" xyz="0 0 0" />
      <geometry>
        <mesh filename="meshes/body.stl" scale="0.001 0.001 0.001" />
        </geometry>
      <material name="Grey">
        <color rgba="0.60 0.60 0.60 1.0" />
        </material>
      </visual>
    <collision>
      <origin rpy="0 0 0" xyz="0 0 0" />
      <geometry>
        <mesh filename="meshes/body.stl" scale="0.001 0.001 0.001" />
        </geometry>
      <material name="Grey">
        <color rgba="0.60 0.60 0.60 1.0" />
        </material>
      </collision>
    <inertial>
      <origin xyz="-0.01501 0.00013 0.06582" />
      <mass value="1.34928" />
      <inertia ixx="0.00340499" ixy="0.00000572" ixz="-0.00004256" iyy="0.00296939" iyz="-0.00000059" izz="0.00317331" />
      </inertial>
    </link>
  <joint name="l_hip_yaw" type="revolute">
    <parent link="body_link" />
    <child link="l_hip_yaw_link" />
    <origin rpy="0 0 0" xyz="0.0 0.035 0.0" />
    <axis xyz="0 0 -1" />
    <limit effort="1000" lower="-2.827433388230814" upper="2.827433388230814" velocity="100" />
    <dynamics damping="0.1" friction="0.0" />
    </joint>
  <transmission name="l_hip_yaw_tran">
    <type>transmission_interface/SimpleTransmission</type>
    <joint name="l_hip_yaw">
      <hardwareInterface>hardware_interface/EffortJointInterface</hardwareInterface>
      </joint>
    <actuator name="l_hip_yaw_motor">
      <hardwareInterface>hardware_interface/EffortJointInterface</hardwareInterface>
      <mechanicalReduction>1</mechanicalReduction>
      </actuator>
    </transmission>
  <link name="l_hip_yaw_link">
    <visual>
      <origin rpy="0 0 0" xyz="0 0 0" />
      <geometry>
        <mesh filename="meshes/ll1.stl" scale="0.001 0.001 0.001" />
        </geometry>
      <material name="Grey">
        <color rgba="0.60 0.60 0.60 1.0" />
        </material>
      </visual>
    <collision>
      <origin rpy="0 0 0" xyz="0 0 0" />
      <geometry>
        <mesh filename="meshes/ll1.stl" scale="0.001 0.001 0.001" />
        </geometry>
      <material name="Grey">
        <color rgba="0.60 0.60 0.60 1.0" />
        </material>
      </collision>
    <inertial>
      <origin xyz="-0.00157 0.00000 -0.00774" />
      <mass value="0.01181" />
      <inertia ixx="0.00000151" ixy="0.0" ixz="0.00000001" iyy="0.00000430" iyz="0.0" izz="0.00000412" />
      </inertial>
    </link>
  <joint name="l_hip_roll" type="revolute">
    <parent link="l_hip_yaw_link" />
    <child link="l_hip_roll_link" />
    <origin rpy="0 0 0" xyz="-0.024 0.0 -0.0285" />
    <axis xyz="-1 0 0" />
    <limit effort="1000" lower="-2.827433388230814" upper="2.827433388230814" velocity="100" />
    <dynamics damping="0.1" friction="0.0" />
    </joint>
  <transmission name="l_hip_roll_tran">
    <type>transmission_interface/SimpleTransmission</type>
    <joint name="l_hip_roll">
      <hardwareInterface>hardware_interface/EffortJointInterface</hardwareInterface>
      </joint>
    <actuator name="l_hip_roll_motor">
      <hardwareInterface>hardware_interface/EffortJointInterface</hardwareInterface>
      <mechanicalReduction>1</mechanicalReduction>
      </actuator>
    </transmission>
  <link name="l_hip_roll_link">
    <visual>
      <origin rpy="0 0 0" xyz="0 0 0" />
      <geometry>
        <mesh filename="meshes/ll2.stl" scale="0.001 0.001 0.001" />
        </geometry>
      <material name="Grey">
        <color rgba="0.60 0.60 0.60 1.0" />
        </material>
      </visual>
    <collision>
      <origin rpy="0 0 0" xyz="0 0 0" />
      <geometry>
        <mesh filename="meshes/ll2.stl" scale="0.001 0.001 0.001" />
        </geometry>
      <material name="Grey">
        <color rgba="0.60 0.60 0.60 1.0" />
        </material>
      </collision>
    <inertial>
      <origin xyz="0.00388 0.00028 -0.01214" />
      <mass value="0.17886" />
      <inertia ixx="0.00004661" ixy="-0.00000101" ixz="-0.00000131" iyy="0.00012523" iyz="-0.00000006" izz="0.00010857" />
      </inertial>
    </link>
  <joint name="l_hip_pitch" type="revolute">
    <parent link="l_hip_roll_link" />
    <child link="l_hip_pitch_link" />
    <origin rpy="0 0 0" xyz="0.0241 0.019 0.0" />
    <axis xyz="0 1 0" />
    <limit effort="1000" lower="-2.827433388230814" upper="2.827433388230814" velocity="100" />
    <dynamics damping="0.1" friction="0.0" />
    </joint>
  <transmission name="l_hip_pitch_tran">
    <type>transmission_interface/SimpleTransmission</type>
    <joint name="l_hip_pitch">
      <hardwareInterface>hardware_interface/EffortJointInterface</hardwareInterface>
      </joint>
    <actuator name="l_hip_pitch_motor">
      <hardwareInterface>hardware_interface/EffortJointInterface</hardwareInterface>
      <mechanicalReduction>1</mechanicalReduction>
      </actuator>
    </transmission>
  <link name="l_hip_pitch_link">
    <visual>
      <origin rpy="0 0 0" xyz="0 0 0" />
      <geometry>
        <mesh filename="meshes/ll3.stl" scale="0.001 0.001 0.001" />
        </geometry>
      <material name="Grey">
        <color rgba="0.60 0.60 0.60 1.0" />
        </material>
      </visual>
    <collision>
      <origin rpy="0 0 0" xyz="0 0 0" />
      <geometry>
        <mesh filename="meshes/ll3.stl" scale="0.001 0.001 0.001" />
        </geometry>
      <material name="Grey">
        <color rgba="0.60 0.60 0.60 1.0" />
        </material>
      </collision>
    <inertial>
      <origin xyz="0.00059 -0.01901 -0.08408" />
      <mass value="0.11543" />
      <inertia ixx="0.00010499" ixy="-0.00000001" ixz="-0.00000071" iyy="0.00009613" iyz="0.00000353" izz="0.00002493" />
      </inertial>
    </link>
  <joint name="l_knee" type="revolute">
    <parent link="l_hip_pitch_link" />
    <child link="l_knee_link" />
    <origin rpy="0 0 0" xyz="0.0 0.0 -0.11015" />
    <axis xyz="0 1 0" />
    <limit effort="1000" lower="-2.827433388230814" upper="2.827433388230814" velocity="100" />
    <dynamics damping="0.1" friction="0.0" />
    </joint>
  <transmission name="l_knee_tran">
    <type>transmission_interface/SimpleTransmission</type>
    <joint name="l_knee">
      <hardwareInterface>hardware_interface/EffortJointInterface</hardwareInterface>
      </joint>
    <actuator name="l_knee_motor">
      <hardwareInterface>hardware_interface/EffortJointInterface</hardwareInterface>
      <mechanicalReduction>1</mechanicalReduction>
      </actuator>
    </transmission>
  <link name="l_knee_link">
    <visual>
      <origin rpy="0 0 0" xyz="0 0 0" />
      <geometry>
        <mesh filename="meshes/ll4.stl" scale="0.001 0.001 0.001" />
        </geometry>
      <material name="Grey">
        <color rgba="0.60 0.60 0.60 1.0" />
        </material>
      </visual>
    <collision>
      <origin rpy="0 0 0" xyz="0 0 0" />
      <geometry>
        <mesh filename="meshes/ll4.stl" scale="0.001 0.001 0.001" />
        </geometry>
      <material name="Grey">
        <color rgba="0.60 0.60 0.60 1.0" />
        </material>
      </collision>
    <inertial>
      <origin xyz="0.00000 -0.02151 -0.05500" />
      <mass value="0.04015" />
      <inertia ixx="0.00003715" ixy="0.0" ixz="0.0" iyy="0.00002751" iyz="0.0" izz="0.00001511" />
      </inertial>
    </link>
  <joint name="l_ank_pitch" type="revolute">
    <parent link="l_knee_link" />
    <child link="l_ank_pitch_link" />
    <origin rpy="0 0 0" xyz="0 0 -0.110" />
    <axis xyz="0 -1 0" />
    <limit effort="1000" lower="-2.827433388230814" upper="2.827433388230814" velocity="100" />
    <dynamics damping="0.1" friction="0.0" />
    </joint>
  <transmission name="l_ank_pitch_tran">
    <type>transmission_interface/SimpleTransmission</type>
    <joint name="l_ank_pitch">
      <hardwareInterface>hardware_interface/EffortJointInterface</hardwareInterface>
      </joint>
    <actuator name="l_ank_pitch_motor">
      <hardwareInterface>hardware_interface/EffortJointInterface</hardwareInterface>
      <mechanicalReduction>1</mechanicalReduction>
      </actuator>
    </transmission>
  <link name="l_ank_pitch_link">
    <visual>
      <origin rpy="0 0 0" xyz="0 0 0" />
      <geometry>
        <mesh filename="meshes/ll5.stl" scale="0.001 0.001 0.001" />
        </geometry>
      <material name="Grey">
        <color rgba="0.60 0.60 0.60 1.0" />
        </material>
      </visual>
    <collision>
      <origin rpy="0 0 0" xyz="0 0 0" />
      <geometry>
        <mesh filename="meshes/ll5.stl" scale="0.001 0.001 0.001" />
        </geometry>
      <material name="Grey">
        <color rgba="0.60 0.60 0.60 1.0" />
        </material>
      </collision>
    <inertial>
      <origin xyz="-0.02022 -0.01872 0.01214" />
      <mass value="0.17886" />
      <inertia ixx="0.00004661" ixy="-0.00000101" ixz="0.00000131" iyy="0.00012523" iyz="0.00000006" izz="0.00010857" />
      </inertial>
    </link>
  <joint name="l_ank_roll" type="revolute">
    <parent link="l_ank_pitch_link" />
    <child link="l_ank_roll_link" />
    <origin rpy="0 0 0" xyz="-0.0241 -0.019 0" />
    <axis xyz="1 0 0" />
    <limit effort="1000" lower="-2.827433388230814" upper="2.827433388230814" velocity="100" />
    <dynamics damping="0.1" friction="0.0" />
    </joint>
  <transmission name="l_ank_roll_tran">
    <type>transmission_interface/SimpleTransmission</type>
    <joint name="l_ank_roll">
      <hardwareInterface>hardware_interface/EffortJointInterface</hardwareInterface>
      </joint>
    <actuator name="l_ank_roll_motor">
      <hardwareInterface>hardware_interface/EffortJointInterface</hardwareInterface>
      <mechanicalReduction>1</mechanicalReduction>
      </actuator>
    </transmission>
  <link name="l_ank_roll_link">
    <visual>
      <origin rpy="0 0 0" xyz="0 0 0" />
      <geometry>
        <mesh filename="meshes/ll6.stl" scale="0.001 0.001 0.001" />
        </geometry>
      <material name="Grey">
        <color rgba="0.60 0.60 0.60 1.0" />
        </material>
      </visual>
    <collision>
      <origin rpy="0 0 0" xyz="0 0 0" />
      <geometry>
        <mesh filename="meshes/ll6.stl" scale="0.001 0.001 0.001" />
        </geometry>
      <material name="Grey">
        <color rgba="0.60 0.60 0.60 1.0" />
        </material>
      </collision>
    <inertial>
      <origin xyz="0.02373 0.01037 -0.02760" />
      <mass value="0.06934" />
      <inertia ixx="0.00004034" ixy="-0.00000019" ixz="0.00000012" iyy="0.00007874" iyz="0.00000101" izz="0.00011579" />
      </inertial>
    </link>
  <joint name="r_hip_yaw" type="revolute">
    <parent link="body_link" />
    <child link="r_hip_yaw_link" />
    <origin rpy="0 0 0" xyz="0.0 -0.035 0.0" />
    <axis xyz="0 0 -1" />
    <limit effort="1000" lower="-2.827433388230814" upper="2.827433388230814" velocity="100" />
    <dynamics damping="0.1" friction="0.0" />
    </joint>
  <transmission name="r_hip_yaw_tran">
    <type>transmission_interface/SimpleTransmission</type>
    <joint name="r_hip_yaw">
      <hardwareInterface>hardware_interface/EffortJointInterface</hardwareInterface>
      </joint>
    <actuator name="r_hip_yaw_motor">
      <hardwareInterface>hardware_interface/EffortJointInterface</hardwareInterface>
      <mechanicalReduction>1</mechanicalReduction>
      </actuator>
    </transmission>
  <link name="r_hip_yaw_link">
    <visual>
      <origin rpy="0 0 0" xyz="0 0 0" />
      <geometry>
        <mesh filename="meshes/rl1.stl" scale="0.001 0.001 0.001" />
        </geometry>
      <material name="Grey">
        <color rgba="0.60 0.60 0.60 1.0" />
        </material>
      </visual>
    <collision>
      <origin rpy="0 0 0" xyz="0 0 0" />
      <geometry>
        <mesh filename="meshes/rl1.stl" scale="0.001 0.001 0.001" />
        </geometry>
      <material name="Grey">
        <color rgba="0.60 0.60 0.60 1.0" />
        </material>
      </collision>
    <inertial>
      <origin xyz="-0.00157 0.00000 -0.00774" />
      <mass value="0.01181" />
      <inertia ixx="0.00000151" ixy="0.0" ixz="0.00000001" iyy="0.00000430" iyz="0.0" izz="0.00000412" />
      </inertial>
    </link>
  <joint name="r_hip_roll" type="revolute">
    <parent link="r_hip_yaw_link" />
    <child link="r_hip_roll_link" />
    <origin rpy="0 0 0" xyz="-0.024 0.0 -0.0285" />
    <axis xyz="-1 0 0" />
    <limit effort="1000" lower="-2.827433388230814" upper="2.827433388230814" velocity="100" />
    <dynamics damping="0.1" friction="0.0" />
    </joint>
  <transmission name="r_hip_roll_tran">
    <type>transmission_interface/SimpleTransmission</type>
    <joint name="r_hip_roll">
      <hardwareInterface>hardware_interface/EffortJointInterface</hardwareInterface>
      </joint>
    <actuator name="r_hip_roll_motor">
      <hardwareInterface>hardware_interface/EffortJointInterface</hardwareInterface>
      <mechanicalReduction>1</mechanicalReduction>
      </actuator>
    </transmission>
  <link name="r_hip_roll_link">
    <visual>
      <origin rpy="0 0 0" xyz="0 0 0" />
      <geometry>
        <mesh filename="meshes/rl2.stl" scale="0.001 0.001 0.001" />
        </geometry>
      <material name="Grey">
        <color rgba="0.60 0.60 0.60 1.0" />
        </material>
      </visual>
    <collision>
      <origin rpy="0 0 0" xyz="0 0 0" />
      <geometry>
        <mesh filename="meshes/rl2.stl" scale="0.001 0.001 0.001" />
        </geometry>
      <material name="Grey">
        <color rgba="0.60 0.60 0.60 1.0" />
        </material>
      </collision>
    <inertial>
      <origin xyz="0.00388 -0.00028 -0.01214" />
      <mass value="0.17886" />
      <inertia ixx="0.00004661" ixy="0.00000101" ixz="-0.00000131" iyy="0.00012523" iyz="0.00000006" izz="0.00010857" />
      </inertial>
    </link>
  <joint name="r_hip_pitch" type="revolute">
    <parent link="r_hip_roll_link" />
    <child link="r_hip_pitch_link" />
    <origin rpy="0 0 0" xyz="0.0241 -0.019 0.0" />
    <axis xyz="0 -1 0" />
    <limit effort="1000" lower="-2.827433388230814" upper="2.827433388230814" velocity="100" />
    <dynamics damping="0.1" friction="0.0" />
    </joint>
  <transmission name="r_hip_pitch_tran">
    <type>transmission_interface/SimpleTransmission</type>
    <joint name="r_hip_pitch">
      <hardwareInterface>hardware_interface/EffortJointInterface</hardwareInterface>
      </joint>
    <actuator name="r_hip_pitch_motor">
      <hardwareInterface>hardware_interface/EffortJointInterface</hardwareInterface>
      <mechanicalReduction>1</mechanicalReduction>
      </actuator>
    </transmission>
  <link name="r_hip_pitch_link">
    <visual>
      <origin rpy="0 0 0" xyz="0 0 0" />
      <geometry>
        <mesh filename="meshes/rl3.stl" scale="0.001 0.001 0.001" />
        </geometry>
      <material name="Grey">
        <color rgba="0.60 0.60 0.60 1.0" />
        </material>
      </visual>
    <collision>
      <origin rpy="0 0 0" xyz="0 0 0" />
      <geometry>
        <mesh filename="meshes/rl3.stl" scale="0.001 0.001 0.001" />
        </geometry>
      <material name="Grey">
        <color rgba="0.60 0.60 0.60 1.0" />
        </material>
      </collision>
    <inertial>
      <origin xyz="0.00059 0.01901 -0.08408" />
      <mass value="0.11543" />
      <inertia ixx="0.00010499" ixy="0.00000001" ixz="-0.00000071" iyy="0.00009613" iyz="-0.00000353" izz="0.00002493" />
      </inertial>
    </link>
  <joint name="r_knee" type="revolute">
    <parent link="r_hip_pitch_link" />
    <child link="r_knee_link" />
    <origin rpy="0 0 0" xyz="0.0 0.0 -0.11015" />
    <axis xyz="0 -1 0" />
    <limit effort="1000" lower="-2.827433388230814" upper="2.827433388230814" velocity="100" />
    <dynamics damping="0.1" friction="0.0" />
    </joint>
  <transmission name="r_knee_tran">
    <type>transmission_interface/SimpleTransmission</type>
    <joint name="r_knee">
      <hardwareInterface>hardware_interface/EffortJointInterface</hardwareInterface>
      </joint>
    <actuator name="r_knee_motor">
      <hardwareInterface>hardware_interface/EffortJointInterface</hardwareInterface>
      <mechanicalReduction>1</mechanicalReduction>
      </actuator>
    </transmission>
  <link name="r_knee_link">
    <visual>
      <origin rpy="0 0 0" xyz="0 0 0" />
      <geometry>
        <mesh filename="meshes/rl4.stl" scale="0.001 0.001 0.001" />
        </geometry>
      <material name="Grey">
        <color rgba="0.60 0.60 0.60 1.0" />
        </material>
      </visual>
    <collision>
      <origin rpy="0 0 0" xyz="0 0 0" />
      <geometry>
        <mesh filename="meshes/rl4.stl" scale="0.001 0.001 0.001" />
        </geometry>
      <material name="Grey">
        <color rgba="0.60 0.60 0.60 1.0" />
        </material>
      </collision>
    <inertial>
      <origin xyz="0.00000 0.02151 -0.05500" />
      <mass value="0.04015" />
      <inertia ixx="0.00003715" ixy="0.0" ixz="0.0" iyy="0.00002751" iyz="0.0" izz="0.00001511" />
      </inertial>
    </link>
  <joint name="r_ank_pitch" type="revolute">
    <parent link="r_knee_link" />
    <child link="r_ank_pitch_link" />
    <origin rpy="0 0 0" xyz="0 0 -0.110" />
    <axis xyz="0 1 0" />
    <limit effort="1000" lower="-2.827433388230814" upper="2.827433388230814" velocity="100" />
    <dynamics damping="0.1" friction="0.0" />
    </joint>
  <transmission name="r_ank_pitch_tran">
    <type>transmission_interface/SimpleTransmission</type>
    <joint name="r_ank_pitch">
      <hardwareInterface>hardware_interface/EffortJointInterface</hardwareInterface>
      </joint>
    <actuator name="r_ank_pitch_motor">
      <hardwareInterface>hardware_interface/EffortJointInterface</hardwareInterface>
      <mechanicalReduction>1</mechanicalReduction>
      </actuator>
    </transmission>
  <link name="r_ank_pitch_link">
    <visual>
      <origin rpy="0 0 0" xyz="0 0 0" />
      <geometry>
        <mesh filename="meshes/rl5.stl" scale="0.001 0.001 0.001" />
        </geometry>
      <material name="Grey">
        <color rgba="0.60 0.60 0.60 1.0" />
        </material>
      </visual>
    <collision>
      <origin rpy="0 0 0" xyz="0 0 0" />
      <geometry>
        <mesh filename="meshes/rl5.stl" scale="0.001 0.001 0.001" />
        </geometry>
      <material name="Grey">
        <color rgba="0.60 0.60 0.60 1.0" />
        </material>
      </collision>
    <inertial>
      <origin xyz="-0.02022 0.01872 0.01214" />
      <mass value="0.17886" />
      <inertia ixx="0.00004661" ixy="0.00000101" ixz="0.00000131" iyy="0.00012523" iyz="-0.00000006" izz="0.00010857" />
      </inertial>
    </link>
  <joint name="r_ank_roll" type="revolute">
    <parent link="r_ank_pitch_link" />
    <child link="r_ank_roll_link" />
    <origin rpy="0 0 0" xyz="-0.0241 0.019 0" />
    <axis xyz="1 0 0" />
    <limit effort="1000" lower="-2.827433388230814" upper="2.827433388230814" velocity="100" />
    <dynamics damping="0.1" friction="0.0" />
    </joint>
  <transmission name="r_ank_roll_tran">
    <type>transmission_interface/SimpleTransmission</type>
    <joint name="r_ank_roll">
      <hardwareInterface>hardware_interface/EffortJointInterface</hardwareInterface>
      </joint>
    <actuator name="r_ank_roll_motor">
      <hardwareInterface>hardware_interface/EffortJointInterface</hardwareInterface>
      <mechanicalReduction>1</mechanicalReduction>
      </actuator>
    </transmission>
  <link name="r_ank_roll_link">
    <visual>
      <origin rpy="0 0 0" xyz="0 0 0" />
      <geometry>
        <mesh filename="meshes/rl6.stl" scale="0.001 0.001 0.001" />
        </geometry>
      <material name="Grey">
        <color rgba="0.60 0.60 0.60 1.0" />
        </material>
      </visual>
    <collision>
      <origin rpy="0 0 0" xyz="0 0 0" />
      <geometry>
        <mesh filename="meshes/rl6.stl" scale="0.001 0.001 0.001" />
        </geometry>
      <material name="Grey">
        <color rgba="0.60 0.60 0.60 1.0" />
        </material>
      </collision>
    <inertial>
      <origin xyz="0.02373 -0.01037 -0.02760" />
      <mass value="0.06934" />
      <inertia ixx="0.00004034" ixy="0.00000019" ixz="0.00000012" iyy="0.00007874" iyz="-0.00000101" izz="0.00011579" />
      </inertial>
    </link>
  <joint name="l_sho_pitch" type="revolute">
    <parent link="body_link" />
    <child link="l_sho_pitch_link" />
    <origin rpy="0 0 0" xyz="-0.001 0.06 0.111" />
    <axis xyz="0 1 0" />
    <limit effort="1000" lower="-2.827433388230814" upper="2.827433388230814" velocity="100" />
    <dynamics damping="0.1" friction="0.0" />
    </joint>
  <transmission name="l_sho_pitch_tran">
    <type>transmission_interface/SimpleTransmission</type>
    <joint name="l_sho_pitch">
      <hardwareInterface>hardware_interface/EffortJointInterface</hardwareInterface>
      </joint>
    <actuator name="l_sho_pitch_motor">
      <hardwareInterface>hardware_interface/EffortJointInterface</hardwareInterface>
      <mechanicalReduction>1</mechanicalReduction>
      </actuator>
    </transmission>
  <link name="l_sho_pitch_link">
    <visual>
      <origin rpy="0 0 0" xyz="0 0 0" />
      <geometry>
        <mesh filename="meshes/la1.stl" scale="0.001 0.001 0.001" />
        </geometry>
      <material name="Grey">
        <color rgba="0.60 0.60 0.60 1.0" />
        </material>
      </visual>
    <collision>
      <origin rpy="0 0 0" xyz="0 0 0" />
      <geometry>
        <mesh filename="meshes/la1.stl" scale="0.001 0.001 0.001" />
        </geometry>
      <material name="Grey">
        <color rgba="0.60 0.60 0.60 1.0" />
        </material>
      </collision>
    <inertial>
      <origin xyz="0.0 0.00823 -0.00233" />
      <mass value="0.01176" />
      <inertia ixx="0.00000165" ixy="0.0" ixz="0.0" iyy="0.00000387" iyz="0.00000031" izz="0.00000397" />
      </inertial>
    </link>
  <joint name="l_sho_roll" type="revolute">
    <parent link="l_sho_pitch_link" />
    <child link="l_sho_roll_link" />
    <origin rpy="0 0 0" xyz="0.019 0.0285 -0.010" />
    <axis xyz="-1 0 0" />
    <limit effort="1000" lower="-2.827433388230814" upper="2.827433388230814" velocity="100" />
    <dynamics damping="0.1" friction="0.0" />
    </joint>
  <transmission name="l_sho_roll_tran">
    <type>transmission_interface/SimpleTransmission</type>
    <joint name="l_sho_roll">
      <hardwareInterface>hardware_interface/EffortJointInterface</hardwareInterface>
      </joint>
    <actuator name="l_sho_roll_motor">
      <hardwareInterface>hardware_interface/EffortJointInterface</hardwareInterface>
      <mechanicalReduction>1</mechanicalReduction>
      </actuator>
    </transmission>
  <link name="l_sho_roll_link">
    <visual>
      <origin rpy="0 0 0" xyz="0 0 0" />
      <geometry>
        <mesh filename="meshes/la2.stl" scale="0.001 0.001 0.001" />
        </geometry>
      <material name="Grey">
        <color rgba="0.60 0.60 0.60 1.0" />
        </material>
      </visual>
    <collision>
      <origin rpy="0 0 0" xyz="0 0 0" />
      <geometry>
        <mesh filename="meshes/la2.stl" scale="0.001 0.001 0.001" />
        </geometry>
      <material name="Grey">
        <color rgba="0.60 0.60 0.60 1.0" />
        </material>
      </collision>
    <inertial>
      <origin xyz="-0.01844 0.04514 0.00028" />
      <mass value="0.17758" />
      <inertia ixx="0.00022804" ixy="-0.00000001" ixz="0.00000003" iyy="0.00003042" iyz="0.00000059" izz="0.00023474" />
      </inertial>
    </link>
  <joint name="l_el" type="revolute">
    <parent link="l_sho_roll_link" />
    <child link="l_el_link" />
    <origin rpy="0 0 0" xyz="0.0 0.0904 -0.0001" />
    <axis xyz="1 0 0" />
    <limit effort="1000" lower="-2.827433388230814" upper="2.827433388230814" velocity="100" />
    <dynamics damping="0.1" friction="0.0" />
    </joint>
  <transmission name="l_el_tran">
    <type>transmission_interface/SimpleTransmission</type>
    <joint name="l_el">
      <hardwareInterface>hardware_interface/EffortJointInterface</hardwareInterface>
      </joint>
    <actuator name="l_el_motor">
      <hardwareInterface>hardware_interface/EffortJointInterface</hardwareInterface>
      <mechanicalReduction>1</mechanicalReduction>
      </actuator>
    </transmission>
  <link name="l_el_link">
    <visual>
      <origin rpy="0 0 0" xyz="0 0 0" />
      <geometry>
        <mesh filename="meshes/la3.stl" scale="0.001 0.001 0.001" />
        </geometry>
      <material name="Grey">
        <color rgba="0.60 0.60 0.60 1.0" />
        </material>
      </visual>
    <collision>
      <origin rpy="0 0 0" xyz="0 0 0" />
      <geometry>
        <mesh filename="meshes/la3.stl" scale="0.001 0.001 0.001" />
        </geometry>
      <material name="Grey">
        <color rgba="0.60 0.60 0.60 1.0" />
        </material>
      </collision>
    <inertial>
      <origin xyz="-0.01900 0.07033 0.00380" />
      <mass value="0.04127" />
      <inertia ixx="0.00006196" ixy="0.0" ixz="0.0" iyy="0.00001231" iyz="-0.00000372" izz="0.00006854" />
      </inertial>
    </link>
  <joint name="r_sho_pitch" type="revolute">
    <parent link="body_link" />
    <child link="r_sho_pitch_link" />
    <origin rpy="0 0 0" xyz="-0.001 -0.06 0.111" />
    <axis xyz="0 -1 0" />
    <limit effort="1000" lower="-2.827433388230814" upper="2.827433388230814" velocity="100" />
    <dynamics damping="0.1" friction="0.0" />
    </joint>
  <transmission name="r_sho_pitch_tran">
    <type>transmission_interface/SimpleTransmission</type>
    <joint name="r_sho_pitch">
      <hardwareInterface>hardware_interface/EffortJointInterface</hardwareInterface>
      </joint>
    <actuator name="r_sho_pitch_motor">
      <hardwareInterface>hardware_interface/EffortJointInterface</hardwareInterface>
      <mechanicalReduction>1</mechanicalReduction>
      </actuator>
    </transmission>
  <link name="r_sho_pitch_link">
    <visual>
      <origin rpy="0 0 0" xyz="0 0 0" />
      <geometry>
        <mesh filename="meshes/ra1.stl" scale="0.001 0.001 0.001" />
        </geometry>
      <material name="Grey">
        <color rgba="0.60 0.60 0.60 1.0" />
        </material>
      </visual>
    <collision>
      <origin rpy="0 0 0" xyz="0 0 0" />
      <geometry>
        <mesh filename="meshes/ra1.stl" scale="0.001 0.001 0.001" />
        </geometry>
      <material name="Grey">
        <color rgba="0.60 0.60 0.60 1.0" />
        </material>
      </collision>
    <inertial>
      <origin xyz="0.0 -0.00823 -0.00233" />
      <mass value="0.01176" />
      <inertia ixx="0.00000165" ixy="0.0" ixz="0.0" iyy="0.00000387" iyz="-0.00000031" izz="0.00000397" />
      </inertial>
    </link>
  <joint name="r_sho_roll" type="revolute">
    <parent link="r_sho_pitch_link" />
    <child link="r_sho_roll_link" />
    <origin rpy="0 0 0" xyz="0.019 -0.0285 -0.010" />
    <axis xyz="-1 0 0" />
    <limit effort="1000" lower="-2.827433388230814" upper="2.827433388230814" velocity="100" />
    <dynamics damping="0.1" friction="0.0" />
    </joint>
  <transmission name="r_sho_roll_tran">
    <type>transmission_interface/SimpleTransmission</type>
    <joint name="r_sho_roll">
      <hardwareInterface>hardware_interface/EffortJointInterface</hardwareInterface>
      </joint>
    <actuator name="r_sho_roll_motor">
      <hardwareInterface>hardware_interface/EffortJointInterface</hardwareInterface>
      <mechanicalReduction>1</mechanicalReduction>
      </actuator>
    </transmission>
  <link name="r_sho_roll_link">
    <visual>
      <origin rpy="0 0 0" xyz="0 0 0" />
      <geometry>
        <mesh filename="meshes/ra2.stl" scale="0.001 0.001 0.001" />
        </geometry>
      <material name="Grey">
        <color rgba="0.60 0.60 0.60 1.0" />
        </material>
      </visual>
    <collision>
      <origin rpy="0 0 0" xyz="0 0 0" />
      <geometry>
        <mesh filename="meshes/ra2.stl" scale="0.001 0.001 0.001" />
        </geometry>
      <material name="Grey">
        <color rgba="0.60 0.60 0.60 1.0" />
        </material>
      </collision>
    <inertial>
      <origin xyz="-0.01844 -0.04514 0.00028" />
      <mass value="0.17758" />
      <inertia ixx="0.00022804" ixy="0.00000001" ixz="0.00000003" iyy="0.00003042" iyz="-0.00000059" izz="0.00023474" />
      </inertial>
    </link>
  <joint name="r_el" type="revolute">
    <parent link="r_sho_roll_link" />
    <child link="r_el_link" />
    <origin rpy="0 0 0" xyz="0.0 -0.0904 -0.0001" />
    <axis xyz="1 0 0" />
    <limit effort="1000" lower="-2.827433388230814" upper="2.827433388230814" velocity="100" />
    <dynamics damping="0.1" friction="0.0" />
    </joint>
  <transmission name="r_el_tran">
    <type>transmission_interface/SimpleTransmission</type>
    <joint name="r_el">
      <hardwareInterface>hardware_interface/EffortJointInterface</hardwareInterface>
      </joint>
    <actuator name="r_el_motor">
      <hardwareInterface>hardware_interface/EffortJointInterface</hardwareInterface>
      <mechanicalReduction>1</mechanicalReduction>
      </actuator>
    </transmission>
  <link name="r_el_link">
    <visual>
      <origin rpy="0 0 0" xyz="0 0 0" />
      <geometry>
        <mesh filename="meshes/ra3.stl" scale="0.001 0.001 0.001" />
        </geometry>
      <material name="Grey">
        <color rgba="0.60 0.60 0.60 1.0" />
        </material>
      </visual>
    <collision>
      <origin rpy="0 0 0" xyz="0 0 0" />
      <geometry>
        <mesh filename="meshes/ra3.stl" scale="0.001 0.001 0.001" />
        </geometry>
      <material name="Grey">
        <color rgba="0.60 0.60 0.60 1.0" />
        </material>
      </collision>
    <inertial>
      <origin xyz="-0.01900 -0.07033 0.00380" />
      <mass value="0.04127" />
      <inertia ixx="0.00006196" ixy="0.0" ixz="0.0" iyy="0.00001231" iyz="0.00000372" izz="0.00006854" />
      </inertial>
    </link>
  <joint name="head_pan" type="revolute">
    <parent link="body_link" />
    <child link="head_pan_link" />
    <origin rpy="0 0 0" xyz="-0.001 0.0 0.1365" />
    <axis xyz="0 0 1" />
    <limit effort="1000" lower="-2.827433388230814" upper="2.827433388230814" velocity="100" />
    <dynamics damping="0.1" friction="0.0" />
    </joint>
  <transmission name="head_pan_tran">
    <type>transmission_interface/SimpleTransmission</type>
    <joint name="head_pan">
      <hardwareInterface>hardware_interface/EffortJointInterface</hardwareInterface>
      </joint>
    <actuator name="head_pan_motor">
      <hardwareInterface>hardware_interface/EffortJointInterface</hardwareInterface>
      <mechanicalReduction>1</mechanicalReduction>
      </actuator>
    </transmission>
  <link name="head_pan_link">
    <visual>
      <origin rpy="0 0 0" xyz="0 0 0" />
      <geometry>
        <mesh filename="meshes/h1.stl" scale="0.001 0.001 0.001" />
        </geometry>
      <material name="Grey">
        <color rgba="0.60 0.60 0.60 1.0" />
        </material>
      </visual>
    <collision>
      <origin rpy="0 0 0" xyz="0 0 0" />
      <geometry>
        <mesh filename="meshes/h1.stl" scale="0.001 0.001 0.001" />
        </geometry>
      <material name="Grey">
        <color rgba="0.60 0.60 0.60 1.0" />
        </material>
      </collision>
    <inertial>
      <origin xyz="0.00233 0.00000 0.00823" />
      <mass value="0.01176" />
      <inertia ixx="0.00000397" ixy="0.0" ixz="-0.00000031" iyy="0.00000165" iyz="0.0" izz="0.00000387" />
      </inertial>
    </link>
  <joint name="head_tilt" type="revolute">
    <parent link="head_pan_link" />
    <child link="head_tilt_link" />
    <origin rpy="0 0 0" xyz="0.010 0.019 0.0285" />
    <axis xyz="0 -1 0" />
    <limit effort="1000" lower="-2.827433388230814" upper="2.827433388230814" velocity="100" />
    <dynamics damping="0.1" friction="0.0" />
    </joint>
  <transmission name="head_tilt_tran">
    <type>transmission_interface/SimpleTransmission</type>
    <joint name="head_tilt">
      <hardwareInterface>hardware_interface/EffortJointInterface</hardwareInterface>
      </joint>
    <actuator name="head_tilt_motor">
      <hardwareInterface>hardware_interface/EffortJointInterface</hardwareInterface>
      <mechanicalReduction>1</mechanicalReduction>
      </actuator>
    </transmission>
  <link name="head_tilt_link">
    <visual>
      <origin rpy="0 0 0" xyz="0 0 0" />
      <geometry>
        <mesh filename="meshes/h2.stl" scale="0.001 0.001 0.001" />
        </geometry>
      <material name="Grey">
        <color rgba="0.60 0.60 0.60 1.0" />
        </material>
      </visual>
    <collision>
      <origin rpy="0 0 0" xyz="0 0 0" />
      <geometry>
        <mesh filename="meshes/h2.stl" scale="0.001 0.001 0.001" />
        </geometry>
      <material name="Grey">
        <color rgba="0.60 0.60 0.60 1.0" />
        </material>
      </collision>
    <inertial>
      <origin xyz="0.00230 -0.01863 0.02770" />
      <mass value="0.13631" />
      <inertia ixx="0.00010612" ixy="0.00000011" ixz="-0.00000910" iyy="0.00008721" iyz="0.00000084" izz="0.00004529" />
      </inertial>
    </link>
  <joint name="cam" type="fixed">
    <origin rpy="-1.5707963267948966 0 -1.5707963267948966" xyz="0.01425 -0.019 0.04975" />
    <parent link="head_tilt_link" />
    <child link="cam_link" />
    </joint>
  <joint name="cam_gazebo" type="fixed">
    <origin rpy="0 0 0" xyz="0.01425 -0.019 0.04975" />
    <parent link="head_tilt_link" />
    <child link="cam_gazebo_link" />
    </joint>
  <link name="cam_link">
  </link>
  <link name="cam_gazebo_link">
  </link>
  </robot>
